Workbook

Sheet Ratios
B1: Case Study Part 3 - Ratio Analysis
B2: Tootsie Roll vs The Hershey Co.
B4: Your next step in the Tootsie Roll case study is to analyze the company's financial ratios vs. its largest competitor, The Hershey Company. Your analysis needs to include liquidity, asset management (activity), debt management (leverage), profitability and market ratios.
C9: Tootsie Roll | I9: Hershey
C10: 2023 | D10: 2022 | I10: 2023 | J10: 2022
B12: Current ratio | C12: ='FS, TR'!B30/'FS, TR'!B47 -> 3.5900325 | D12: ='FS, TR'!C30/'FS, TR'!C47 -> 3.4285397 | H12: Current ratio | I12: ='FS, HSY'!B30/'FS, HSY'!B44 -> 0.96800607 | J12: ='FS, HSY'!C30/'FS, HSY'!C44 -> 0.80450786
B13: Quick ratio | C13: =('FS, TR'!B30-'FS, TR'!B26)/'FS, TR'!B47 -> 2.5896847 | D13: =('FS, TR'!C30-'FS, TR'!C26)/'FS, TR'!C47 -> 2.4936428 | H13: Quick ratio | I13: =('FS, HSY'!B30-'FS, HSY'!B28)/'FS, HSY'!B44 -> 0.52224839 | J13: =('FS, HSY'!C30-'FS, HSY'!C28)/'FS, HSY'!C44 -> 0.44434098
B14: Total Asset Turnover | C14: ='FS, TR'!B6/'FS, TR'!B39 -> 0.7094904 | D14: ='FS, TR'!C6/'FS, TR'!C39 -> 0.67430719 | H14: Total Asset Turnover | I14: ='FS, HSY'!B6/'FS, HSY'!B36 -> 0.9380028 | J14: ='FS, HSY'!C6/'FS, HSY'!C36 -> 0.95163625
B15: Avg Collection Period | C15: =('FS, TR'!B24/'FS, TR'!B6)*365 -> 26.362416 | D15: =('FS, TR'!C24/'FS, TR'!C6)*365 -> 31.111897 | H15: Avg Collection Period | I15: =('FS, HSY'!B27/'FS, HSY'!B6)*365 -> 26.92525 | J15: =('FS, HSY'!C27/'FS, HSY'!C6)*365 -> 24.914269
B16: Debt Ratio | C16: ='FS, TR'!B51/'FS, TR'!B39 -> 0.24094999 | D16: ='FS, TR'!C51/'FS, TR'!C39 -> 0.23154875 | H16: Debt Ratio | I16: ='FS, HSY'!B48/'FS, HSY'!B36 -> 0.6556241 | J16: ='FS, HSY'!C48/'FS, HSY'!C36 -> 0.69863931
B17: Times Interest Earned | C17: ='FS, TR'!B11/'FS, TR'!B12 -> 356.76855 | D17: ='FS, TR'!C11/'FS, TR'!C12 -> 944.66346 | H17: Times Interest Earned | I17: ='FS, HSY'!B13/'FS, HSY'!B14 -> -16.871674 | J17: ='FS, HSY'!C13/'FS, HSY'!C14 -> -16.435274
B18: Net Profit margin | C18: ='FS, TR'!B16/'FS, TR'!B6 -> 0.11946475 | D18: ='FS, TR'!C16/'FS, TR'!C6 -> 0.11053903 | H18: Net Profit margin | I18: ='FS, HSY'!B18/'FS, HSY'!B6 -> 0.1667522 | J18: ='FS, HSY'!C18/'FS, HSY'!C6 -> 0.15786262
B19: Return On Assets | C19: ='FS, TR'!B16/'FS, TR'!B39 -> 0.084759095 | D19: ='FS, TR'!C16/'FS, TR'!C39 -> 0.074537265 | H19: Return On Assets | I19: ='FS, HSY'!B18/'FS, HSY'!B36 -> 0.15641403 | J19: ='FS, HSY'!C18/'FS, HSY'!C36 -> 0.15022779
B20: Return On Equity | C20: ='FS, TR'!B16/'FS, TR'!B60 -> 0.1116647 | D20: ='FS, TR'!C16/'FS, TR'!C60 -> 0.096996738 | H20: Return On Equity | I20: ='FS, HSY'!B18/'FS, HSY'!B58 -> 0.45419564 | J20: ='FS, HSY'!C18/'FS, HSY'!C58 -> 0.49849828
B22: Market Price per Share | C22: 31.41 | H22: Market Price per Share | I22: 193.36
B23: Earning Per Share (EPS) | C23: 1.324 | H23: Earning Per Share (EPS) | I23: 9
B25: Current PE Ratio | C25: 23.72 | H25: Current PE Ratio | I25: =I22/I23 -> 21.484444

Sheet Sheet1
A1: Analysis:
A2: (1) Liquidity
A3: Current Ratio anslyis: Tootsie Roll has a much stronger liquidity position compared to Hershey in both 2023 and 2022. A current ratio above 1 indicates that Tootsie Roll has sufficient current assets to cover its liabilities, while Hershey is below the desired threshold of 1, indicating potential liquidity risk.
A4: Quick Ratio analyis: Tootsie Roll again performs better in terms of immediate liquidity in both 2023 and 2022, with a quick ratio over 1. Hershey's quick ratio below 1 suggests challenges in meeting short-term obligations without relying on inventory sales.
A5: Therefore, Tootsie Roll has a stronger liquidity position compared to Hershey.
A6: (2) Asset Management
A7: Total Asset Turnover:
A8: In 2023, Tootsie Roll: 0.71 and Hershey: 0.94
A9: In 2022, Tootsie Roll: 0.67 and Hershey: 0.95
A10: Analysis: In 2022, Hershey demonstrated a higher asset turnover, efficiently using its assets to generate sales. Tootsie Roll’s asset turnover was slightly lower in 2022 compared to 2023, reflecting room for improvement. In 2023, Hershey outperforms Tootsie Roll in utilizing its assets to generate sales. A higher asset turnover ratio for Hershey implies it is more efficient in asset management.
A11: Average Collection Period:
A12: In 2023, Tootsie Roll: 26.36 days and Hershey: 747.99 days
... A54: Overall, Hershey appears to have a stronger financial position than Tootsie Roll. It has a more efficient asset management strategy, a higher level of profitability, and a higher market valuation. However, Tootsie Roll has a stronger liquidity position and a lower level of debt, which could provide it with greater financial flexibility.

Sheet FS, TR
A1: Financial Statements, Tootsie Roll ($000s)
A4: INCOME STATEMENT | B4: 2023 | C4: 2022 | D4: 2021 | E4: 2020
A6: Total Revenue | B6: 769365 | C6: 686970 | D6: 570776 | E6: 471063
A7: COGS & Royalty cost | B7: 512525 | C7: 454239 | D7: 371535 | E7: 300702
A8: Gross profit | B8: 256840 | C8: =C6-C7 -> 232731 | D8: =D6-D7 -> 199241 | E8: =E6-E7 -> 170361
A9: SG & A expenses | B9: 155012 | C9: =121976-104 -> 121872 | D9: =132108-46 -> 132062 | E9: =112117-164 -> 111953
A10: Other Income/(Expense) | B10: =18066+337 -> 18403 | C10: -12614 | D10: 18596 | E10: 18018
A11: EBIT | B11: =B8-B9+B10 -> 120231 | C11: =C8-C9+C10 -> 98245 | D11: =D8-D9+D10 -> 85775 | E11: =E8-E9+E10 -> 76426
A12: Interest Expense | B12: 337 | C12: 104 | D12: 46 | E12: 164
A13: Before-tax earnings | B13: =B11-B12 -> 119894 | C13: =C11-C12 -> 98141 | D13: =D11-D12 -> 85729 | E13: =E11-E12 -> 76262
A14: Taxes | B14: 28008 | C14: 22249 | D14: 20421 | E14: 17288
A15: Minority Interest | B15: 26 | C15: 45 | D15: 18 | E15: 21
A16: Net Income Attributable to Tootsie Roll Industries | B16: =B13-B14+B15 -> 91912 | C16: =C13-C14+C15 -> 75937 | D16: =D13-D14+D15 -> 65326 | E16: =E13-E14+E15 -> 58995
A19: BALANCE SHEET, as of Dec 31 | B19: 2023 | C19: 2022 | D19: 2021 | E19: 2020
A21: ASSETS
A22: Cash & Cash Equivalents | B22: =75915+375 -> 76290 | C22: =53270+365 -> 53635 | D22: =105840+386 -> 106226 | E22: =166841+415 -> 167256
A23: Investments | B23: 95507 | C23: 96128 | D23: 39968 | E23: 42090
A24: Accounts receivable | B24: 55568 | C24: 58556 | D24: 54921 | E24: 41209
A25: Other Receivables | B25: 9165 | C25: 4299 | D25: 3920 | E25: 3894
A26: Inventory | B26: =51240+43681 -> 94921 | C26: =43595+40671 -> 84266 | D26: =31431+24074 -> 55505 | E26: =35583+23996 -> 59579
A27: Income Taxes Receivable | B27: 0 | C27: 0 | D27: 0 | E27: 0
A28: Prepaid Expenses | B28: 9200 | C28: 12144 | D28: 7761 | E28: 6844
A29: Deferred Income Taxes | B29: 0 | C29: 0 | D29: 0 | E29: 0
A30: Current assets | B30: =SUM(B22:B29) -> 340651 | C30: =SUM(C22:C29) -> 309028 | D30: =SUM(D22:D29) -> 268301 | E30: =SUM(E22:E29) -> 320872
A32: Gross Prop & Equip | B32: 670498 | C32: 641182 | D32: 621402 | E32: 583332
A33: Less Accum Depreciation | B33: -447520 | C33: -429139 | D33: -412496 | E33: -396004
A34: Net Prop & Equip | B34: =SUM(B32:B33) -> 222978 | C34: =SUM(C32:C33) -> 212043 | D34: =SUM(D32:D33) -> 208906 | E34: =SUM(E32:E33) -> 187328
A35: Goodwill | B35: 73237 | C35: 73237 | D35: 73237 | E35: 73237
A36: Trademarks | B36: 175024 | C36: 175024 | D36: 175024 | E36: 175024
A37: Investments (long term) | B37: 255606 | C37: 247528 | D37: 291175 | E37: 220020
A38: Other Assets | B38: =15189+1706 -> 16895 | C38: =465+1454 -> 1919 | D38: =603+1372 -> 1975 | E38: =2514+4525+1038 -> 8077
A39: Total Assets | B39: =B30+SUM(B34:B38) -> 1084391 | C39: =C30+SUM(C34:C38) -> 1018779 | D39: =D30+SUM(D34:D38) -> 1018618 | E39: =E30+SUM(E34:E38) -> 984558
A41: LIABILITIES AND EQUITIES
A42: Accounts payable | B42: 15816 | C42: 25246 | D42: 14969 | E42: 13025
A43: Bank Loans (short term) | B43: 1088 | C43: 1051 | D43: 939 | E43: 832
A44: Dividends payable | B44: 6250 | C44: 6154 | D44: 6042 | E44: 5948
A45: Accrued Liabilities | B45: 61690 | C45: 54444 | D45: 53896 | E45: 45099
A46: Other current liabilities | B46: =665+1289+8090 -> 10044 | C46: =658+791+1790 -> 3239 | D46: =616+1072+2434 -> 4122 | E46: =544+780+3793 -> 5117
A47: Current liabilities | B47: =SUM(B42:B46) -> 94888 | C47: =SUM(C42:C46) -> 90134 | D47: =SUM(D42:D46) -> 79968 | E47: =SUM(E42:E46) -> 70021
A48: Bank Loans | B48: 0 | C48: 0 | D48: 0 | E48: 0
...

Sheet FS, HSY
A1: Financial Statements, Hershey Co. ($000s)
A4: INCOME STATEMENT | B4: 2023 | C4: 2022 | D4: 2021 | E4: 2020
A6: Total revenue | B6: 11164992 | C6: 10419294 | D6: 8971337 | E6: 8149719
A7: COGS | B7: 6167176 | C7: 5920509 | D7: 4922739 | E7: 4448450
A8: Gross profit | B8: =B6-B7 -> 4997816 | C8: =C6-C7 -> 4498785 | D8: =D6-D7 -> 4048598 | E8: =E6-E7 -> 3701269
A9: SG & A expenses | B9: 2436508 | C9: 2236009 | D9: 2001351 | E9: 1890925
A10: Long-lived Asset Impairment | B10: 0 | C10: 0 | D10: 0 | E10: 9143
A11: Goodwill Impairment charges | E11: 0
A12: Business Realignment Costs | B12: 441 | C12: 1989 | D12: 3525 | E12: 18503
A13: EBIT | B13: =B8-SUM(B9:B12) -> 2560867 | C13: =C8-SUM(C9:C12) -> 2260787 | D13: =D8-SUM(D9:D12) -> 2043722 | E13: =E8-SUM(E9:E12) -> 1782698
A14: Interest Expense | B14: -151785 | C14: -137557 | D14: -127417 | E14: -149374
A15: Other Income (Expense) | B15: -237218 | C15: -206159 | D15: -119081 | E15: -138327
A16: Before-tax earnings | B16: =B13+B15+B14 -> 2171864 | C16: =C13+C15+C14 -> 1917071 | D16: =D13+D15+D14 -> 1797224 | E16: =E13+E15+E14 -> 1494997
A17: Taxes | B17: 310077 | C17: 272254 | D17: 314405 | E17: 219584
A18: Net income | B18: =B16-B17 -> 1861787 | C18: =C16-C17 -> 1644817 | D18: =D16-D17 -> 1482819 | E18: =E16-E17 -> 1275413
A19: Less: Net loss attributable to noncontrolling interest | C19: 0 | D19: 5307 | E19: -3295
A20: Net income attributable to Hershey | B20: =B18-B19 -> 1861787 | C20: =C18-C19 -> 1644817 | D20: =D18-D19 -> 1477512 | E20: =E18-E19 -> 1278708
A22: BALANCE SHEET, as of Dec 31 | B22: 2023 | C22: 2022 | D22: 2021 | E22: =E4 -> 2020
A24: ASSETS
A25: Cash & investments | B25: 401902 | C25: 463889 | D25: 329266 | E25: 1143987
A26: Short term Investments | B26: 0 | C26: 0 | D26: 0 | E26: 0
A27: Accounts receivable | B27: 823617 | C27: 711203 | D27: 671464 | E27: 615233
A28: Inventory | B28: 1340996 | C28: 1173119 | D28: 988511 | E28: 964207
A29: Prepaid Expenses & Other | B29: 345588 | C29: 272195 | D29: 256965 | E29: 254478
A30: Current Assets | B30: =SUM(B25:B29) -> 2912103 | C30: =SUM(C25:C29) -> 2620406 | D30: =SUM(D25:D29) -> 2246206 | E30: =SUM(E25:E29) -> 2977905
A32: Property, Plant & Equip, Net | B32: 3309678 | C32: 2769702 | D32: 2586187 | E32: 2285255
A33: Goodwill | B33: 2696050 | C33: 2606956 | D33: 2633174 | E33: 1988215
A34: Other intangibles | B34: 1879229 | C34: 1966269 | D34: 2037588 | E34: 1295214
A35: Other Assets | B35: =1061427+44454 -> 1105881 | C35: =40498+944989 -> 985487 | D35: =868203+40873 -> 909076 | E35: =555887+29369 -> 585256
A36: Total Assets | B36: =B30+SUM(B32:B35) -> 11902941 | C36: =C30+SUM(C32:C35) -> 10948820 | D36: =D30+SUM(D32:D35) -> 10412231 | E36: =E30+SUM(E32:E35) -> 9131845
A38: LIABILITIES AND EQUITY
A39: Accounts payable | B39: 1086183 | C39: 970558 | D39: 692338 | E39: 580058
A40: Accrued Liabilities | B40: 867815 | C40: 832518 | D40: 855638 | E40: 781766
A41: Short Term Debt | B41: 719839 | C41: 693790 | D41: 939423 | E41: 74041
A42: Current Portion, Long Term Debt | B42: 305058 | C42: 753578 | D42: 2844 | E42: 438829
A43: Accrued income taxes | B43: 29457 | C43: 6710 | D43: 3070 | E43: 17051
A44: Current Liabilities | B44: =SUM(B39:B43) -> 3008352 | C44: =SUM(C39:C43) -> 3257154 | D44: =SUM(D39:D43) -> 2493313 | E44: =SUM(E39:E43) -> 1891745
A45: Long-term debt | B45: 3789132 | C45: 3343977 | D45: 4086627 | E45: 4089755
A46: Other liabilities | B46: 660673 | C46: 719742 | D46: 787058 | E46: 683434
A47: Deferred Income Taxes | B47: 345698 | C47: 328403 | D47: 288004 | E47: 229028
...
